-------------------------------------------------------------------------------
Test set: TestSuite
-------------------------------------------------------------------------------
Tests run: 6, Failures: 1, Errors: 0, Skipped: 0, Time elapsed: 34.99 s <<< FAILURE! -- in TestSuite
testcases.ValidLoginTest.loginWithMultipleUsers[locked_out_user, secret_sauce](3) -- Time elapsed: 8.772 s <<< FAILURE!
java.lang.AssertionError: expected [true] but found [false]
	at org.testng.Assert.fail(Assert.java:110)
	at org.testng.Assert.failNotEquals(Assert.java:1413)
	at org.testng.Assert.assertTrue(Assert.java:56)
	at org.testng.Assert.assertTrue(Assert.java:66)
	at testcases.ValidLoginTest.loginWithMultipleUsers(ValidLoginTest.java:31)
	at java.base/jdk.internal.reflect.DirectMethodHandleAccessor.invoke(DirectMethodHandleAccessor.java:103)
	at java.base/java.lang.reflect.Method.invoke(Method.java:580)
	at org.testng.internal.invokers.MethodInvocationHelper.invokeMethod(MethodInvocationHelper.java:139)
	at org.testng.internal.invokers.TestInvoker.invokeMethod(TestInvoker.java:677)
	at org.testng.internal.invokers.TestInvoker.invokeTestMethod(TestInvoker.java:221)
	at org.testng.internal.invokers.TestMethodWithDataProviderMethodWorker.call(TestMethodWithDataProviderMethodWorker.java:80)
	at org.testng.internal.invokers.TestMethodWithDataProviderMethodWorker.call(TestMethodWithDataProviderMethodWorker.java:17)
	at java.base/java.util.concurrent.FutureTask.run(FutureTask.java:317)
	at java.base/java.util.concurrent.Executors$RunnableAdapter.call(Executors.java:572)
	at java.base/java.util.concurrent.FutureTask.run(FutureTask.java:317)
	at java.base/java.util.concurrent.ThreadPoolExecutor.runWorker(ThreadPoolExecutor.java:1144)
	at java.base/java.util.concurrent.ThreadPoolExecutor$Worker.run(ThreadPoolExecutor.java:642)
	at java.base/java.lang.Thread.run(Thread.java:1575)

